<?xml version="1.0" ?>
<!-- =================================================================================== -->
<!-- |    This document was autogenerated by xacro from /home/walkie/walkie_ws/src/bringup/walkie3_description/urdf/walkie_cr3.xacro | -->
<!-- |    EDITING THIS FILE BY HAND IS NOT RECOMMENDED                                 | -->
<!-- =================================================================================== -->
<robot name="cr3_robot">
    <material name="black">
        <color rgba="0.3 0.3 0.3 1.000" />
    </material>
    <transmission name="Revolute_1_tran">
        <type>transmission_interface/SimpleTransmission</type>
        <joint name="r_motor_joint">
            <hardwareInterface>hardware_interface/EffortJointInterface</hardwareInterface>
        </joint>
        <actuator name="Revolute_1_actr">
            <hardwareInterface>hardware_interface/EffortJointInterface</hardwareInterface>
            <mechanicalReduction>1</mechanicalReduction>
        </actuator>
    </transmission>
    <transmission name="Revolute_2_tran">
        <type>transmission_interface/SimpleTransmission</type>
        <joint name="l_motor_joint">
            <hardwareInterface>hardware_interface/EffortJointInterface</hardwareInterface>
        </joint>
        <actuator name="Revolute_2_actr">
            <hardwareInterface>hardware_interface/EffortJointInterface</hardwareInterface>
            <mechanicalReduction>1</mechanicalReduction>
        </actuator>
    </transmission>
    <transmission name="Slider_5_tran">
        <type>transmission_interface/SimpleTransmission</type>
        <joint name="lift_joint">
            <hardwareInterface>hardware_interface/EffortJointInterface</hardwareInterface>
        </joint>
        <actuator name="Slider_5_actr">
            <hardwareInterface>hardware_interface/EffortJointInterface</hardwareInterface>
            <mechanicalReduction>1</mechanicalReduction>
        </actuator>
    </transmission>
    <transmission name="Revolute_6_tran">
        <type>transmission_interface/SimpleTransmission</type>
        <joint name="camera_servo_joint">
            <hardwareInterface>hardware_interface/EffortJointInterface</hardwareInterface>
        </joint>
        <actuator name="Revolute_6_actr">
            <hardwareInterface>hardware_interface/EffortJointInterface</hardwareInterface>
            <mechanicalReduction>1</mechanicalReduction>
        </actuator>
    </transmission>
    <gazebo>
        <plugin filename="libgazebo_ros_control.so" name="control" />
        <plugin name="gazebo_ros_control">
            <robotNamespace>/</robotNamespace>
        </plugin>
    </gazebo>
    <gazebo reference="base_link">
        <material>Gazebo/Silver</material>
        <mu1>0.2</mu1>
        <mu2>0.2</mu2>
        <selfCollide>true</selfCollide>
        <gravity>true</gravity>
    </gazebo>
    <gazebo reference="rm_1">
        <material>Gazebo/Silver</material>
        <mu1>0.2</mu1>
        <mu2>0.2</mu2>
        <selfCollide>true</selfCollide>
    </gazebo>
    <gazebo reference="lm_1">
        <material>Gazebo/Silver</material>
        <mu1>0.2</mu1>
        <mu2>0.2</mu2>
        <selfCollide>true</selfCollide>
    </gazebo>
    <gazebo reference="front_lidar_1">
        <material>Gazebo/Silver</material>
        <mu1>0.2</mu1>
        <mu2>0.2</mu2>
        <selfCollide>true</selfCollide>
    </gazebo>
    <gazebo reference="back_lidar_1">
        <material>Gazebo/Silver</material>
        <mu1>0.2</mu1>
        <mu2>0.2</mu2>
        <selfCollide>true</selfCollide>
    </gazebo>
    <gazebo reference="lift_1">
        <material>Gazebo/Silver</material>
        <mu1>0.2</mu1>
        <mu2>0.2</mu2>
        <selfCollide>true</selfCollide>
    </gazebo>
    <gazebo reference="camera_case_1">
        <material>Gazebo/Silver</material>
        <mu1>0.2</mu1>
        <mu2>0.2</mu2>
        <selfCollide>true</selfCollide>
    </gazebo>
    <gazebo reference="zed2i_1">
        <material>Gazebo/Silver</material>
        <mu1>0.2</mu1>
        <mu2>0.2</mu2>
        <selfCollide>true</selfCollide>
    </gazebo>
    <link name="base_link">
        <!-- <inertial>
    <origin xyz="-0.079364700486305 -5.907967612059166e-05 0.5515631622465227" rpy="0 0 0"/>
    <mass value="1504.8082003936406"/>
    <inertia ixx="238.112569" iyy="242.107575" izz="68.584451" ixy="-0.0643" iyz="-0.00296" ixz="40.564727"/>
  </inertial> -->
        <visual>
            <origin rpy="0 0 0" xyz="0 0 0" />
            <geometry>
                <mesh filename="package://walkie3_description/meshes/base_link.stl" scale="0.001 0.001 0.001" />
            </geometry>
            <material name="black" />
        </visual>
        <collision>
            <origin rpy="0 0 0" xyz="0 0 0" />
            <geometry>
                <mesh filename="package://walkie3_description/meshes/base_link.stl" scale="0.001 0.001 0.001" />
            </geometry>
        </collision>
        <inertial>
            <mass value="0.1" />
            <origin xyz="0 0 0" rpy="0 0 0" />
            <inertia ixx="0.03" iyy="0.03" izz="0.03" ixy="0.0" ixz="0.0" iyz="0.0" />
        </inertial>
    </link>
    <link name="r_motor">
        <inertial>
            <origin rpy="0 0 0" xyz="-2.6062051822206556e-15 0.029600000000000043 1.734723475976807e-18" />
            <mass value="1.2840689772481653" />
            <inertia ixx="0.002126" ixy="-0.0" ixz="0.0" iyy="0.003732" iyz="0.0" izz="0.002126" />
        </inertial>
        <visual>
            <origin rpy="0 0 0" xyz="0.0015 0.1968 -0.012" />
            <geometry>
                <mesh filename="package://walkie3_description/meshes/rm_1.stl" scale="0.001 0.001 0.001" />
            </geometry>
            <material name="black" />
        </visual>
        <collision>
            <origin rpy="0 0 0" xyz="0.0015 0.1968 -0.012" />
            <geometry>
                <mesh filename="package://walkie3_description/meshes/rm_1.stl" scale="0.001 0.001 0.001" />
            </geometry>
        </collision>
    </link>
    <link name="l_motor">
        <inertial>
            <origin rpy="0 0 0" xyz="-2.6062051822206556e-15 -0.029600000000000043 1.734723475976807e-18" />
            <mass value="1.2840689772481653" />
            <inertia ixx="0.002126" ixy="-0.0" ixz="-0.0" iyy="0.003732" iyz="-0.0" izz="0.002126" />
        </inertial>
        <visual>
            <origin rpy="0 0 0" xyz="0.0015 -0.1968 -0.012" />
            <geometry>
                <mesh filename="package://walkie3_description/meshes/lm_1.stl" scale="0.001 0.001 0.001" />
            </geometry>
            <material name="black" />
        </visual>
        <collision>
            <origin rpy="0 0 0" xyz="0.0015 -0.1968 -0.012" />
            <geometry>
                <mesh filename="package://walkie3_description/meshes/lm_1.stl" scale="0.001 0.001 0.001" />
            </geometry>
        </collision>
    </link>
    <link name="front_lidar">
        <inertial>
            <origin rpy="0 0 0" xyz="0.0 -1.322960035965437e-08 0.0025000000000000022" />
            <mass value="0.0493230046613599" />
            <inertia ixx="5e-06" ixy="0.0" ixz="0.0" iyy="5e-06" iyz="0.0" izz="1e-05" />
        </inertial>
        <visual>
            <origin rpy="0 0 0" xyz="-0.2345 -0.210318 -0.1775" />
            <geometry>
                <mesh filename="package://walkie3_description/meshes/front_lidar_1.stl" scale="0.001 0.001 0.001" />
            </geometry>
            <material name="black" />
        </visual>
        <collision>
            <origin rpy="0 0 0" xyz="-0.2345 -0.210318 -0.1775" />
            <geometry>
                <mesh filename="package://walkie3_description/meshes/front_lidar_1.stl" scale="0.001 0.001 0.001" />
            </geometry>
        </collision>
    </link>
    <link name="back_lidar">
        <inertial>
            <origin rpy="0 0 0" xyz="2.488404678147038e-07 2.488404678424594e-07 0.0025000000000000577" />
            <mass value="0.04932300466135975" />
            <inertia ixx="5e-06" ixy="0.0" ixz="-0.0" iyy="5e-06" iyz="-0.0" izz="1e-05" />
        </inertial>
        <visual>
            <origin rpy="0 0 0" xyz="0.223042 0.199542 -0.1775" />
            <geometry>
                <mesh filename="package://walkie3_description/meshes/back_lidar_1.stl" scale="0.001 0.001 0.001" />
            </geometry>
            <material name="black" />
        </visual>
        <collision>
            <origin rpy="0 0 0" xyz="0.223042 0.199542 -0.1775" />
            <geometry>
                <mesh filename="package://walkie3_description/meshes/back_lidar_1.stl" scale="0.001 0.001 0.001" />
            </geometry>
        </collision>
    </link>
    <link name="lift">
        <inertial>
            <origin rpy="0 0 0" xyz="-0.0595 -7.19910242530375e-17 -0.22049999999999992" />
            <mass value="9.197469540000002" />
            <inertia ixx="0.161423" ixy="0.0" ixz="0.0" iyy="0.159915" iyz="0.0" izz="0.023216" />
        </inertial>
        <visual>
            <origin rpy="0 0 0" xyz="-0.2135 -0.0045 -0.5015" />
            <geometry>
                <mesh filename="package://walkie3_description/meshes/lift_1.stl" scale="0.001 0.001 0.001" />
            </geometry>
            <material name="black" />
        </visual>
        <collision>
            <origin rpy="0 0 0" xyz="-0.2135 -0.0045 -0.5015" />
            <geometry>
                <mesh filename="package://walkie3_description/meshes/lift_1.stl" scale="0.001 0.001 0.001" />
            </geometry>
        </collision>
    </link>
    <link name="camera_servo">
        <inertial>
            <origin rpy="0 0 0" xyz="0.0009771735426644251 0.08953172714997108 -2.220446049250313e-16" />
            <mass value="0.23417405554980755" />
            <inertia ixx="0.001135" ixy="-0.0" ixz="0.0" iyy="3.5e-05" iyz="-0.0" izz="0.001141" />
        </inertial>
        <visual>
            <origin rpy="0 0 0" xyz="0.1215 0.09 -1.389" />
            <geometry>
                <mesh filename="package://walkie3_description/meshes/camera_case_1.stl" scale="0.001 0.001 0.001" />
            </geometry>
            <material name="black" />
        </visual>
        <collision>
            <origin rpy="0 0 0" xyz="0.1215 0.09 -1.389" />
            <geometry>
                <mesh filename="package://walkie3_description/meshes/camera_case_1.stl" scale="0.001 0.001 0.001" />
            </geometry>
        </collision>
    </link>
    <link name="camera_case">
        <inertial>
            <origin rpy="0 0 0" xyz="0.018649000000000054 2.498531024240378e-17 -0.013862999999999959" />
            <mass value="1.428746199196806" />
            <inertia ixx="0.00378" ixy="0.0" ixz="0.0" iyy="0.000257" iyz="0.0" izz="0.003854" />
        </inertial>
        <visual>
            <origin rpy="0 0 0" xyz="0.111391 -0.0 -1.402863" />
            <geometry>
                <mesh filename="package://walkie3_description/meshes/zed2i_1.stl" scale="0.001 0.001 0.001" />
            </geometry>
            <material name="black" />
        </visual>
        <collision>
            <origin rpy="0 0 0" xyz="0.111391 -0.0 -1.402863" />
            <geometry>
                <mesh filename="package://walkie3_description/meshes/zed2i_1.stl" scale="0.001 0.001 0.001" />
            </geometry>
        </collision>
    </link>
    <joint name="r_motor_joint" type="continuous">
        <origin rpy="0 0 0" xyz="-0.0015 -0.1968 0.012" />
        <parent link="base_link" />
        <child link="r_motor" />
        <axis xyz="0.0 -1.0 0.0" />
    </joint>
    <joint name="l_motor_joint" type="continuous">
        <origin rpy="0 0 0" xyz="-0.0015 0.1968 0.012" />
        <parent link="base_link" />
        <child link="l_motor" />
        <axis xyz="-0.0 -1.0 0.0" />
    </joint>
    <joint name="Rigid_3" type="fixed">
        <origin rpy="0 0 0.785" xyz="0.2345 0.210318 0.1775" />
        <parent link="base_link" />
        <child link="front_lidar" />
    </joint>
    <joint name="Rigid_4" type="fixed">
        <origin rpy="0 0 -2.356" xyz="-0.223042 -0.199542 0.1775" />
        <parent link="base_link" />
        <child link="back_lidar" />
    </joint>
    <joint name="lift_joint" type="prismatic">
        <origin rpy="0 0 0" xyz="0.2135 0.0045 0.5015" />
        <parent link="base_link" />
        <child link="lift" />
        <axis xyz="0.0 0.0 1.0" />
        <limit effort="100" lower="0.0" upper="0.245" velocity="100" />
    </joint>
    <joint name="camera_servo_joint" type="continuous">
        <origin rpy="0 0 0" xyz="-0.1215 -0.09 1.389" />
        <parent link="base_link" />
        <child link="camera_servo" />
        <axis xyz="0.0 1.0 0.0" />
    </joint>
    <joint name="Rigid_7" type="fixed">
        <origin rpy="0 0 0" xyz="0.010109 0.09 0.013863" />
        <parent link="camera_servo" />
        <child link="camera_case" />
    </joint>
    <link name="dummy_link" />
    <link name="cr3_base_link">
        <inertial>
            <origin rpy="0 0 0" xyz="-0.0027213 3.915E-07 0.022038" />
            <mass value="0.653" />
            <inertia ixx="0.00075137" ixy="-3.0366E-08" ixz="1.2825E-06" iyy="0.00080094" iyz="2.5423E-09" izz="0.0010902" />
        </inertial>
        <visual>
            <origin rpy="0 0 0" xyz="0 0 0" />
            <geometry>
                <mesh filename="package://dobot_description/meshes/cr3/base_link.STL" />
            </geometry>
            <material name="">
                <color rgba="1 1 1 1" />
            </material>
        </visual>
        <collision>
            <origin rpy="0 0 0" xyz="0 0 0" />
            <geometry>
                <mesh filename="package://dobot_description/meshes/cr3/base_link.STL" />
            </geometry>
        </collision>
    </link>
    <joint name="dummy_joint" type="fixed">
        <parent link="dummy_link" />
        <child link="cr3_base_link" />
    </joint>
    <link name="Link1">
        <inertial>
            <origin rpy="0 0 0" xyz="-3.68657602416735E-05 -0.00394516685385322 0.00364037839421286" />
            <mass value="1.31100598822002" />
            <inertia ixx="0.00202531167977736" ixy="-1.62039964254407E-06" ixz="4.44242218921916E-07" iyy="0.00198085794611413" iyz="0.000256891817572315" izz="0.00183966900872187" />
        </inertial>
        <visual>
            <origin rpy="0 0 0" xyz="0 0 0" />
            <geometry>
                <mesh filename="package://dobot_description/meshes/cr3/Link1.STL" />
            </geometry>
            <material name="">
                <color rgba="1 1 1 1" />
            </material>
        </visual>
        <collision>
            <origin rpy="0 0 0" xyz="0 0 0" />
            <geometry>
                <mesh filename="package://dobot_description/meshes/cr3/Link1.STL" />
            </geometry>
        </collision>
    </link>
    <joint name="joint1" type="revolute">
        <origin rpy="0 0 0" xyz="0 0 0.1283" />
        <parent link="cr3_base_link" />
        <child link="Link1" />
        <axis xyz="0 0 1" />
        <limit effort="0" lower="-3.14" upper="3.14" velocity="0" />
    </joint>
    <link name="Link2">
        <inertial>
            <origin rpy="0 0 0" xyz="-0.129235280055448 1.440541622715E-05 0.133173619961293" />
            <mass value="3.40043726977504" />
            <inertia ixx="0.00450581324845612" ixy="1.58054368766225E-06" ixz="8.56287041890268E-05" iyy="0.00632329822349442" iyz="-4.41201729949356E-07" izz="0.00578241711656701" />
        </inertial>
        <visual>
            <origin rpy="0 0 0" xyz="0 0 0" />
            <geometry>
                <mesh filename="package://dobot_description/meshes/cr3/Link2.STL" />
            </geometry>
            <material name="">
                <color rgba="1 1 1 1" />
            </material>
        </visual>
        <collision>
            <origin rpy="0 0 0" xyz="0 0 0" />
            <geometry>
                <mesh filename="package://dobot_description/meshes/cr3/Link2.STL" />
            </geometry>
        </collision>
    </link>
    <joint name="joint2" type="revolute">
        <origin rpy="1.5708 1.5708 0" xyz="0 0 0" />
        <parent link="Link1" />
        <child link="Link2" />
        <axis xyz="0 0 1" />
        <limit effort="0" lower="-3.14" upper="3.14" velocity="0" />
    </joint>
    <link name="Link3">
        <inertial>
            <origin rpy="0 0 0" xyz="-0.119822632176479 8.63344146663093E-08 0.0099876637825216" />
            <mass value="2.21449412948544" />
            <inertia ixx="0.00236120280734313" ixy="1.81888962826726E-08" ixz="0.000137629457194959" iyy="0.00313635345351584" iyz="-1.39166877342495E-08" izz="0.00285118872456311" />
        </inertial>
        <visual>
            <origin rpy="0 0 0" xyz="0 0 0" />
            <geometry>
                <mesh filename="package://dobot_description/meshes/cr3/Link3.STL" />
            </geometry>
            <material name="">
                <color rgba="1 1 1 1" />
            </material>
        </visual>
        <collision>
            <origin rpy="0 0 0" xyz="0 0 0" />
            <geometry>
                <mesh filename="package://dobot_description/meshes/cr3/Link3.STL" />
            </geometry>
        </collision>
    </link>
    <joint name="joint3" type="revolute">
        <origin rpy="0 0 0" xyz="-0.274 0 0" />
        <parent link="Link2" />
        <child link="Link3" />
        <axis xyz="0 0 1" />
        <limit effort="0" lower="-2.86" upper="2.86" velocity="0" />
    </joint>
    <link name="Link4">
        <inertial>
            <origin rpy="0 0 0" xyz="1.74679534498573E-07 0.0034522361215461 -0.0028730999658578" />
            <mass value="0.842272956366123" />
            <inertia ixx="0.00100389823526424" ixy="-3.26498724132116E-09" ixz="-3.83652674720848E-09" iyy="0.000793473566890046" iyz="0.000133420135294005" izz="0.000993889852029541" />
        </inertial>
        <visual>
            <origin rpy="0 0 0" xyz="0 0 0" />
            <geometry>
                <mesh filename="package://dobot_description/meshes/cr3/Link4.STL" />
            </geometry>
            <material name="">
                <color rgba="1 1 1 1" />
            </material>
        </visual>
        <collision>
            <origin rpy="0 0 0" xyz="0 0 0" />
            <geometry>
                <mesh filename="package://dobot_description/meshes/cr3/Link4.STL" />
            </geometry>
        </collision>
    </link>
    <joint name="joint4" type="revolute">
        <origin rpy="0 0 -1.5708" xyz="-0.23 0 0.1283" />
        <parent link="Link3" />
        <child link="Link4" />
        <axis xyz="0 0 1" />
        <limit effort="0" lower="-3.14" upper="3.14" velocity="0" />
    </joint>
    <link name="Link5">
        <inertial>
            <origin rpy="0 0 0" xyz="-1.74603758796282E-07 -0.00333192403958193 -0.00286780844130663" />
            <mass value="0.843692877114241" />
            <inertia ixx="0.0010085532680982" ixy="-7.28325271824168E-09" ixz="9.25818664621925E-09" iyy="0.000794614679668754" iyz="-0.000133904812596915" izz="0.000998497358703575" />
        </inertial>
        <visual>
            <origin rpy="0 0 0" xyz="0 0 0" />
            <geometry>
                <mesh filename="package://dobot_description/meshes/cr3/Link5.STL" />
            </geometry>
            <material name="">
                <color rgba="1 1 1 1" />
            </material>
        </visual>
        <collision>
            <origin rpy="0 0 0" xyz="0 0 0" />
            <geometry>
                <mesh filename="package://dobot_description/meshes/cr3/Link5.STL" />
            </geometry>
        </collision>
    </link>
    <joint name="joint5" type="revolute">
        <origin rpy="1.5708 0 0" xyz="0 -0.116 0" />
        <parent link="Link4" />
        <child link="Link5" />
        <axis xyz="0 0 1" />
        <limit effort="0" lower="-3.14" upper="3.14" velocity="0" />
    </joint>
    <link name="Link6">
        <inertial>
            <origin rpy="0 0 0" xyz="-5.77233004964394E-07 0.000270130842674243 -0.0201386770129675" />
            <mass value="0.159409278145106" />
            <inertia ixx="8.29484481057063E-05" ixy="-1.45209400395148E-09" ixz="-1.72340872805449E-11" iyy="8.35928339777967E-05" iyz="-1.33911019721127E-07" izz="0.000131911087085913" />
        </inertial>
        <visual>
            <origin rpy="0 0 0" xyz="0 0 0" />
            <geometry>
                <mesh filename="package://dobot_description/meshes/cr3/Link6.STL" />
            </geometry>
            <material name="">
                <color rgba="1 1 1 1" />
            </material>
        </visual>
        <collision>
            <origin rpy="0 0 0" xyz="0 0 0" />
            <geometry>
                <mesh filename="package://dobot_description/meshes/cr3/Link6.STL" />
            </geometry>
        </collision>
    </link>
    <joint name="joint6" type="revolute">
        <origin rpy="-1.5708 0 0" xyz="0 0.105 0" />
        <parent link="Link5" />
        <child link="Link6" />
        <axis xyz="0 0 1" />
        <limit effort="0" lower="-6.28" upper="6.28" velocity="0" />
    </joint>
    <material name="cyan">
        <color rgba="0.000 1.000 0.950 1.000" />
    </material>
    <transmission name="Revolute_1_tran">
        <type>transmission_interface/SimpleTransmission</type>
        <joint name="Revolute_1">
            <hardwareInterface>hardware_interface/EffortJointInterface</hardwareInterface>
        </joint>
        <actuator name="Revolute_1_actr">
            <hardwareInterface>hardware_interface/EffortJointInterface</hardwareInterface>
            <mechanicalReduction>1</mechanicalReduction>
        </actuator>
    </transmission>
    <transmission name="Revolute_2_tran">
        <type>transmission_interface/SimpleTransmission</type>
        <joint name="Revolute_2">
            <hardwareInterface>hardware_interface/EffortJointInterface</hardwareInterface>
        </joint>
        <actuator name="Revolute_2_actr">
            <hardwareInterface>hardware_interface/EffortJointInterface</hardwareInterface>
            <mechanicalReduction>1</mechanicalReduction>
        </actuator>
    </transmission>
    <transmission name="Revolute_3_tran">
        <type>transmission_interface/SimpleTransmission</type>
        <joint name="Revolute_3">
            <hardwareInterface>hardware_interface/EffortJointInterface</hardwareInterface>
        </joint>
        <actuator name="Revolute_3_actr">
            <hardwareInterface>hardware_interface/EffortJointInterface</hardwareInterface>
            <mechanicalReduction>1</mechanicalReduction>
        </actuator>
    </transmission>
    <transmission name="Revolute_4_tran">
        <type>transmission_interface/SimpleTransmission</type>
        <joint name="Revolute_4">
            <hardwareInterface>hardware_interface/EffortJointInterface</hardwareInterface>
        </joint>
        <actuator name="Revolute_4_actr">
            <hardwareInterface>hardware_interface/EffortJointInterface</hardwareInterface>
            <mechanicalReduction>1</mechanicalReduction>
        </actuator>
    </transmission>
    <transmission name="Slider_5_tran">
        <type>transmission_interface/SimpleTransmission</type>
        <joint name="Slider_5">
            <hardwareInterface>hardware_interface/EffortJointInterface</hardwareInterface>
        </joint>
        <actuator name="Slider_5_actr">
            <hardwareInterface>hardware_interface/EffortJointInterface</hardwareInterface>
            <mechanicalReduction>1</mechanicalReduction>
        </actuator>
    </transmission>
    <transmission name="Revolute_6_tran">
        <type>transmission_interface/SimpleTransmission</type>
        <joint name="Revolute_6">
            <hardwareInterface>hardware_interface/EffortJointInterface</hardwareInterface>
        </joint>
        <actuator name="Revolute_6_actr">
            <hardwareInterface>hardware_interface/EffortJointInterface</hardwareInterface>
            <mechanicalReduction>1</mechanicalReduction>
        </actuator>
    </transmission>
    <transmission name="Revolute_7_tran">
        <type>transmission_interface/SimpleTransmission</type>
        <joint name="Revolute_7">
            <hardwareInterface>hardware_interface/EffortJointInterface</hardwareInterface>
        </joint>
        <actuator name="Revolute_7_actr">
            <hardwareInterface>hardware_interface/EffortJointInterface</hardwareInterface>
            <mechanicalReduction>1</mechanicalReduction>
        </actuator>
    </transmission>
    <gazebo>
        <plugin filename="libgazebo_ros_control.so" name="control" />
    </gazebo>
    <gazebo reference="base_link">
        <material>Gazebo/Silver</material>
        <mu1>0.2</mu1>
        <mu2>0.2</mu2>
        <selfCollide>true</selfCollide>
        <gravity>true</gravity>
    </gazebo>
    <gazebo reference="clamp2_1">
        <material>Gazebo/Silver</material>
        <mu1>0.2</mu1>
        <mu2>0.2</mu2>
        <selfCollide>true</selfCollide>
    </gazebo>
    <gazebo reference="joint_gripper2_1">
        <material>Gazebo/Silver</material>
        <mu1>0.2</mu1>
        <mu2>0.2</mu2>
        <selfCollide>true</selfCollide>
    </gazebo>
    <gazebo reference="clamp1_1">
        <material>Gazebo/Silver</material>
        <mu1>0.2</mu1>
        <mu2>0.2</mu2>
        <selfCollide>true</selfCollide>
    </gazebo>
    <gazebo reference="joint_gripper1_1">
        <material>Gazebo/Silver</material>
        <mu1>0.2</mu1>
        <mu2>0.2</mu2>
        <selfCollide>true</selfCollide>
    </gazebo>
    <gazebo reference="joint_gripper3_1">
        <material>Gazebo/Silver</material>
        <mu1>0.2</mu1>
        <mu2>0.2</mu2>
        <selfCollide>true</selfCollide>
    </gazebo>
    <gazebo reference="joint_gripper1_1">
        <material>Gazebo/Silver</material>
        <mu1>0.2</mu1>
        <mu2>0.2</mu2>
        <selfCollide>true</selfCollide>
    </gazebo>
    <gazebo reference="joint_gripper2_1">
        <material>Gazebo/Silver</material>
        <mu1>0.2</mu1>
        <mu2>0.2</mu2>
        <selfCollide>true</selfCollide>
    </gazebo>
    <link name="gripper_base_link">
        <inertial>
            <origin rpy="0 0 0" xyz="1.9099884677715165e-13 -8.588463814791657e-18 0.050480059207214864" />
            <mass value="4.156467071923433" />
            <inertia ixx="0.005332" ixy="-0.0" ixz="-0.0" iyy="0.005469" iyz="-0.0" izz="0.003505" />
        </inertial>
        <visual>
            <origin rpy="0 0 0" xyz="0 0 0" />
            <geometry>
                <mesh filename="package://urdfgripper_description/meshes/base_link.stl" scale="0.001 0.001 0.001" />
            </geometry>
            <material name="cyan" />
        </visual>
        <collision>
            <origin rpy="0 0 0" xyz="0 0 0" />
            <geometry>
                <mesh filename="package://urdfgripper_description/meshes/base_link.stl" scale="0.001 0.001 0.001" />
            </geometry>
        </collision>
    </link>
    <link name="clamp2_1">
        <inertial>
            <origin rpy="0 0 0" xyz="-0.0007710681342016981 0.01324999999999889 0.032208454343210485" />
            <mass value="0.3695576413156298" />
            <inertia ixx="0.000228" ixy="0.0" ixz="2.1e-05" iyy="0.000227" iyz="0.0" izz="4.2e-05" />
        </inertial>
        <visual>
            <origin rpy="0 0 0" xyz="0.036 0.01325 -0.1238" />
            <geometry>
                <mesh filename="package://urdfgripper_description/meshes/clamp2_1.stl" scale="0.001 0.001 0.001" />
            </geometry>
            <material name="cyan" />
        </visual>
        <collision>
            <origin rpy="0 0 0" xyz="0.036 0.01325 -0.1238" />
            <geometry>
                <mesh filename="package://urdfgripper_description/meshes/clamp2_1.stl" scale="0.001 0.001 0.001" />
            </geometry>
        </collision>
    </link>
    <link name="joint_gripper2_1">
        <inertial>
            <origin rpy="0 0 0" xyz="0.0014117786083714633 0.007249999999999621 -0.006855934747932696" />
            <mass value="0.01686070551364095" />
            <inertia ixx="1e-06" ixy="-0.0" ixz="0.0" iyy="1e-06" iyz="-0.0" izz="0.0" />
        </inertial>
        <visual>
            <origin rpy="0 0 0" xyz="0.0175 0.0 -0.105" />
            <geometry>
                <mesh filename="package://urdfgripper_description/meshes/joint_gripper2_1.stl" scale="0.001 0.001 0.001" />
            </geometry>
            <material name="cyan" />
        </visual>
        <collision>
            <origin rpy="0 0 0" xyz="0.0175 0.0 -0.105" />
            <geometry>
                <mesh filename="package://urdfgripper_description/meshes/joint_gripper2_1.stl" scale="0.001 0.001 0.001" />
            </geometry>
        </collision>
    </link>
    <link name="clamp1_1">
        <inertial>
            <origin rpy="0 0 0" xyz="0.0007710678210290922 0.013249999999998886 0.03220845433786543" />
            <mass value="0.36955764131562985" />
            <inertia ixx="0.000228" ixy="-0.0" ixz="-2.1e-05" iyy="0.000227" iyz="0.0" izz="4.2e-05" />
        </inertial>
        <visual>
            <origin rpy="0 0 0" xyz="-0.036 0.01325 -0.1238" />
            <geometry>
                <mesh filename="package://urdfgripper_description/meshes/clamp1_1.stl" scale="0.001 0.001 0.001" />
            </geometry>
            <material name="cyan" />
        </visual>
        <collision>
            <origin rpy="0 0 0" xyz="-0.036 0.01325 -0.1238" />
            <geometry>
                <mesh filename="package://urdfgripper_description/meshes/clamp1_1.stl" scale="0.001 0.001 0.001" />
            </geometry>
        </collision>
    </link>
    <!-- <link name="joint_gripper1_1">
  <inertial>
    <origin xyz="-0.0014117788637248198 0.007249999999999619 -0.006855934695334132" rpy="0 0 0"/>
    <mass value="0.01686070551364095"/>
    <inertia ixx="1e-06" iyy="1e-06" izz="0.0" ixy="0.0" iyz="-0.0" ixz="-0.0"/>
  </inertial>
  <visual>
    <origin xyz="-0.020824 0.00725 -0.127512" rpy="0 0 0"/>
    <geometry>
      <mesh filename="package://urdfgripper_description/meshes/joint_gripper1_1.stl" scale="0.001 0.001 0.001"/>
    </geometry>
    <material name="cyan"/>
  </visual>
  <collision>
    <origin xyz="-0.020824 0.00725 -0.127512" rpy="0 0 0"/>
    <geometry>
      <mesh filename="package://urdfgripper_description/meshes/joint_gripper1_1.stl" scale="0.001 0.001 0.001"/>
    </geometry>
  </collision>
</link> -->
    <link name="joint_gripper3_1">
        <inertial>
            <origin rpy="0 0 0" xyz="2.4639675104551738e-14 -2.3953259916310663e-16 -0.01399999999999997" />
            <mass value="0.03492902737584383" />
            <inertia ixx="1e-06" ixy="-0.0" ixz="0.0" iyy="5e-06" iyz="0.0" izz="5e-06" />
        </inertial>
        <visual>
            <origin rpy="0 0 0" xyz="-0.0 -0.0 -0.1278" />
            <geometry>
                <mesh filename="package://urdfgripper_description/meshes/joint_gripper3_1.stl" scale="0.001 0.001 0.001" />
            </geometry>
            <material name="cyan" />
        </visual>
        <collision>
            <origin rpy="0 0 0" xyz="-0.0 -0.0 -0.1278" />
            <geometry>
                <mesh filename="package://urdfgripper_description/meshes/joint_gripper3_1.stl" scale="0.001 0.001 0.001" />
            </geometry>
        </collision>
    </link>
    <!-- <link name="joint_gripper1_2">
  <inertial>
    <origin xyz="0.0014122211362751803 0.007249999999999619 0.0068560653046658565" rpy="0 0 0"/>
    <mass value="0.01686070551364095"/>
    <inertia ixx="1e-06" iyy="1e-06" izz="0.0" ixy="0.0" iyz="-0.0" ixz="-0.0"/>
  </inertial>
  <visual>
    <origin xyz="-0.018 0.00725 -0.1138" rpy="0 0 0"/>
    <geometry>
      <mesh filename="package://urdfgripper_description/meshes/joint_gripper1_1.stl" scale="0.001 0.001 0.001"/>
    </geometry>
    <material name="cyan"/>
  </visual>
  <collision>
    <origin xyz="-0.018 0.00725 -0.1138" rpy="0 0 0"/>
    <geometry>
      <mesh filename="package://urdfgripper_description/meshes/joint_gripper1_1.stl" scale="0.001 0.001 0.001"/>
    </geometry>
  </collision>
</link> -->
    <link name="joint_gripper2_2">
        <inertial>
            <origin rpy="0 0 0" xyz="-0.0014122213916285369 0.007249999999999621 0.006856065252067292" />
            <mass value="0.01686070551364095" />
            <inertia ixx="1e-06" ixy="-0.0" ixz="0.0" iyy="1e-06" iyz="-0.0" izz="0.0" />
        </inertial>
        <visual>
            <origin rpy="0 0 0" xyz="0.018 0.00725 -0.105" />
            <geometry>
                <mesh filename="package://urdfgripper_description/meshes/joint_gripper2_1.stl" scale="0.001 0.001 0.001" />
            </geometry>
            <material name="cyan" />
        </visual>
        <collision>
            <origin rpy="0 0 0" xyz="0.018 0.00725 -0.105" />
            <geometry>
                <mesh filename="package://urdfgripper_description/meshes/joint_gripper2_1.stl" scale="0.001 0.001 0.001" />
            </geometry>
        </collision>
    </link>
    <joint name="Revolute_1" type="continuous">
        <origin rpy="0 -0.84 0" xyz="-0.036 -0.01325 0.1238" />
        <parent link="gripper_base_link" />
        <child link="clamp2_1" />
        <axis xyz="0.0 -1.0 0.0" />
        <mimic joint="Slider_5" multiplier="62.0" offset="0.0" />
    </joint>
    <joint name="Revolute_2" type="continuous">
        <origin rpy="0 -0.07 0" xyz="-0.018 -0.007 -0.023" />
        <parent link="joint_gripper3_1" />
        <child link="joint_gripper2_2" />
        <axis xyz="0.0 -1.0 -0.0" />
        <mimic joint="Slider_5" multiplier="10.0" offset="0.0" />
    </joint>
    <joint name="Revolute_3" type="continuous">
        <origin rpy="0 1.74 0" xyz="0.036 -0.01325 0.1238" />
        <parent link="gripper_base_link" />
        <child link="clamp1_1" />
        <axis xyz="0.0 -1.0 0.0" />
        <mimic joint="Slider_5" multiplier="-62.0" offset="0.0" />
    </joint>
    <joint name="Revolute_4" type="continuous">
        <origin rpy="0 0.58 0" xyz="0.018 0.000 -0.023" />
        <parent link="joint_gripper3_1" />
        <child link="joint_gripper2_1" />
        <axis xyz="0.0 -1.0 0.0" />
        <mimic joint="Slider_5" multiplier="-10.0" offset="0.0" />
    </joint>
    <joint name="Slider_5" type="prismatic">
        <origin rpy="0 0 0" xyz="0.0 0.0 0.1410" />
        <parent link="gripper_base_link" />
        <child link="joint_gripper3_1" />
        <axis xyz="0.0 0.0 1.0" />
        <limit effort="100" lower="-0.011" upper="0.0" velocity="100" />
    </joint>
    <link name="virtual_lidar" />
    <joint name="virtual_lidar_joint" type="fixed">
        <origin rpy="0 0 0" xyz="0 0 0.1775" />
        <parent link="base_link" />
        <child link="virtual_lidar" />
    </joint>
    <joint name="cr3_to_base" type="fixed">
        <origin rpy="0 0 0" xyz="-0.06 0 0.006" />
        <parent link="lift" />
        <child link="dummy_link" />
    </joint>
    <joint name="cr3_to_gripper" type="fixed">
        <origin rpy="0 0 0" xyz="0.00 0.00 0.00" />
        <parent link="Link6" />
        <child link="gripper_base_link" />
    </joint>
    <joint name="zed2i_joint" type="fixed">
        <origin rpy="0 0 0" xyz="0.031804 0.09 -0.015" />
        <parent link="camera_servo" />
        <child link="zed2i_base_link" />
    </joint>
    <material name="zed_mat">
        <color rgba="0.8 0.8 0.8 0.8" />
    </material>
    <material name="zedm_mat">
        <color rgba="0 0 0 0.9" />
    </material>
    <material name="zed2_mat">
        <color rgba="0.25 0.25 0.25 0.99" />
    </material>
    <material name="zed2i_mat">
        <color rgba="0.25 0.25 0.25 0.99" />
    </material>
    <material name="zedx_mat">
        <color rgba="0.25 0.25 0.25 0.99" />
    </material>
    <material name="zedxm_mat">
        <color rgba="0.25 0.25 0.25 0.99" />
    </material>
    <!-- Camera mounting point (the threaded screw hole in the bottom) -->
    <link name="zed2i_base_link" />
    <joint name="zed2i_base_joint" type="fixed">
        <parent link="camera_servo" />
        <child link="zed2i_base_link" />
        <origin rpy="0.0 0.0 0.0" xyz="0.0 0.0 0.0" />
    </joint>
    <!-- Camera Center -->
    <link name="zed2i_camera_center">
        <visual>
            <origin rpy="0 0 0" xyz="-0.01 0 0.0" />
            <geometry>
                <mesh filename="package://zed_interfaces/meshes/zed2i.stl" />
            </geometry>
            <material name="zed2i_mat" />
        </visual>
        <collision>
            <geometry>
                <mesh filename="package://zed_interfaces/meshes/zed2i.stl" />
            </geometry>
        </collision>
        <inertial>
            <mass value="0.1" />
            <origin xyz="0 0 0" rpy="0 0 0" />
            <inertia ixx="0.03" iyy="0.03" izz="0.03" ixy="0.0" ixz="0.0" iyz="0.0" />
        </inertial>
    </link>
    <joint name="zed2i_camera_center_joint" type="fixed">
        <parent link="zed2i_base_link" />
        <child link="zed2i_camera_center" />
        <origin rpy="0 0.0 0" xyz="0 0 0.015" />
    </joint>
    <!-- Left Camera -->
    <link name="zed2i_left_camera_frame" />
    <joint name="zed2i_left_camera_joint" type="fixed">
        <parent link="zed2i_camera_center" />
        <child link="zed2i_left_camera_frame" />
        <origin rpy="0 0 0" xyz="-0.01 0.06 0" />
    </joint>
    <link name="zed2i_left_camera_optical_frame" />
    <joint name="zed2i_left_camera_optical_joint" type="fixed">
        <origin rpy="-1.5707963267948966 0.0 -1.5707963267948966" xyz="0 0 0" />
        <parent link="zed2i_left_camera_frame" />
        <child link="zed2i_left_camera_optical_frame" />
    </joint>
    <!-- Right Camera -->
    <link name="zed2i_right_camera_frame" />
    <joint name="zed2i_right_camera_joint" type="fixed">
        <parent link="zed2i_camera_center" />
        <child link="zed2i_right_camera_frame" />
        <origin rpy="0 0 0" xyz="-0.01 -0.06 0" />
    </joint>
    <link name="zed2i_right_camera_optical_frame" />
    <joint name="zed2i_right_camera_optical_joint" type="fixed">
        <origin rpy="-1.5707963267948966 0.0 -1.5707963267948966" xyz="0 0 0" />
        <parent link="zed2i_right_camera_frame" />
        <child link="zed2i_right_camera_optical_frame" />
    </joint>
    <link name="zed2i_imu_link" />
    <joint name="zed2i_imu_link_joint" type="fixed">
        <parent link="base_link" />
        <child link="zed2i_imu_link" />
        <origin rpy="0.005 -0.006 -0.006" xyz="-0.102 0.037 1.389" />
    </joint>
    <transmission name="trans_joint1">
        <type>transmission_interface/SimpleTransmission</type>
        <joint name="joint1">
            <hardwareInterface>hardware_interface/EffortJointInterface</hardwareInterface>
        </joint>
        <actuator name="joint1_motor">
            <hardwareInterface>hardware_interface/EffortJointInterface</hardwareInterface>
            <mechanicalReduction>1</mechanicalReduction>
        </actuator>
    </transmission>
    <transmission name="trans_joint2">
        <type>transmission_interface/SimpleTransmission</type>
        <joint name="joint2">
            <hardwareInterface>hardware_interface/EffortJointInterface</hardwareInterface>
        </joint>
        <actuator name="joint2_motor">
            <hardwareInterface>hardware_interface/EffortJointInterface</hardwareInterface>
            <mechanicalReduction>1</mechanicalReduction>
        </actuator>
    </transmission>
    <transmission name="trans_joint3">
        <type>transmission_interface/SimpleTransmission</type>
        <joint name="joint3">
            <hardwareInterface>hardware_interface/EffortJointInterface</hardwareInterface>
        </joint>
        <actuator name="joint3_motor">
            <hardwareInterface>hardware_interface/EffortJointInterface</hardwareInterface>
            <mechanicalReduction>1</mechanicalReduction>
        </actuator>
    </transmission>
    <transmission name="trans_joint4">
        <type>transmission_interface/SimpleTransmission</type>
        <joint name="joint4">
            <hardwareInterface>hardware_interface/EffortJointInterface</hardwareInterface>
        </joint>
        <actuator name="joint4_motor">
            <hardwareInterface>hardware_interface/EffortJointInterface</hardwareInterface>
            <mechanicalReduction>1</mechanicalReduction>
        </actuator>
    </transmission>
    <transmission name="trans_joint5">
        <type>transmission_interface/SimpleTransmission</type>
        <joint name="joint5">
            <hardwareInterface>hardware_interface/EffortJointInterface</hardwareInterface>
        </joint>
        <actuator name="joint5_motor">
            <hardwareInterface>hardware_interface/EffortJointInterface</hardwareInterface>
            <mechanicalReduction>1</mechanicalReduction>
        </actuator>
    </transmission>
    <transmission name="trans_joint6">
        <type>transmission_interface/SimpleTransmission</type>
        <joint name="joint6">
            <hardwareInterface>hardware_interface/EffortJointInterface</hardwareInterface>
        </joint>
        <actuator name="joint6_motor">
            <hardwareInterface>hardware_interface/EffortJointInterface</hardwareInterface>
            <mechanicalReduction>1</mechanicalReduction>
        </actuator>
    </transmission>
</robot>

